Workbook
Name ProjectName: 'المدخلات'!$C$5
Name StudyTitle: 'المدخلات'!$C$6
Name City: 'المدخلات'!$C$7
Name District: 'المدخلات'!$C$8
Name Streets: 'المدخلات'!$C$9
Name DeedNo: 'المدخلات'!$C$10
Name UrbanScope: 'المدخلات'!$C$11
Name LandUse: 'المدخلات'!$C$12
Name Developer: 'المدخلات'!$C$13
Name Consultant: 'المدخلات'!$C$14
Name Auditor: 'المدخلات'!$C$15
Name StartDate: 'المدخلات'!$C$16
Name EndDate: 'المدخلات'!$C$17
Name HandoverDate: 'المدخلات'!$C$18
Name LandArea: 'المدخلات'!$C$22
Name BuildRatio: 'المدخلات'!$C$23
Name FAR: 'المدخلات'!$C$24
Name NetRatio: 'المدخلات'!$C$25
Name UnitArea: 'المدخلات'!$C$26
Name ParkPerUnit: 'المدخلات'!$C$27
Name ParkArea: 'المدخلات'!$C$28
Name LandPrice: 'المدخلات'!$C$30
Name LandFeeRate: 'المدخلات'!$C$31
Name ResCostM2: 'المدخلات'!$C$33
Name BasementCostM2: 'المدخلات'!$C$34
Name OtherCostRate: 'المدخلات'!$C$35
Name ContRate: 'المدخلات'!$C$36
Name DevFeeRate: 'المدخلات'!$C$37
Name LoanAmount: 'المدخلات'!$C$39
Name MurabahaRate: 'المدخلات'!$C$40
Name LoanFeeRate: 'المدخلات'!$C$41
Name Months: 'المدخلات'!$C$43
Name ZakatRate: 'المدخلات'!$C$44
Name Footprint: 'الحسابات'!$C$6
Name BUA: 'الحسابات'!$C$7
Name Floors: 'الحسابات'!$C$8
Name NetArea: 'الحسابات'!$C$9
Name Units: 'الحسابات'!$C$10
Name Parking: 'الحسابات'!$C$11
Name BasementArea: 'الحسابات'!$C$12
Name BasementFloors: 'الحسابات'!$C$13
Name LandPurchase: 'الحسابات'!$C$15
Name LandFees: 'الحسابات'!$C$16
Name LandCost: 'الحسابات'!$C$17
Name ResCost: 'الحسابات'!$C$18
Name BasementCost: 'الحسابات'!$C$19
Name DirectCost: 'الحسابات'!$C$20
Name OtherCost: 'الحسابات'!$C$21
Name ContCost: 'الحسابات'!$C$22
Name DevFee: 'الحسابات'!$C$23
Name IndirectCost: 'الحسابات'!$C$24
Name DevCost: 'الحسابات'!$C$25
Name ProjectCost: 'الحسابات'!$C$26
Name LoanFee: 'الحسابات'!$C$27
Name T_Revenue: 'الحسابات'!$C$36
Name T_LandOut: 'الحسابات'!$C$38
Name T_ResOut: 'الحسابات'!$C$39
Name T_BasOut: 'الحسابات'!$C$40
Name T_OtherOut: 'الحسابات'!$C$41
Name T_Murabaha: 'الحسابات'!$C$49

Sheet الملخص التنفيذي
B1: الملخص التنفيذي
B3: عنوان الدراسة | C3: =StudyTitle
B4: موقع المشروع | C4: =District&" - "&City
B6: ملخص الدراسة المالية
B7: العناصر | C7: القيمة (ريال) | E7: البند | F7: مليون ريال
B8: صافي المبيعات - الوحدات السكنية | C8: =T_Revenue | E8: إجمالي الإيرادات | F8: =T_Revenue/1e6
B9: إجمالي الإيرادات | C9: =T_Revenue | E9: تكاليف الأرض | F9: =LandCost/1e6
B10: إجمالي تكاليف الأرض الخام | C10: =LandCost | E10: التكاليف الإنشائية والفنية | F10: =(DevCost+T_Murabaha+T_LoanFeeOut)/1e6
B11: تكاليف الإنشاءات | C11: =ResCost | E11: صافي الربح | F11: =T_NetProfit/1e6
B12: تكاليف تطوير البنية التحتية (القبو والمواقف) | C12: =BasementCost
B13: مصاريف الاستشاري الهندسي | C13: 0
B14: مصاريف المحاسب القانوني | C14: 0
B15: تكاليف الإشراف والمتابعة والعمولة | C15: 0
B16: تكاليف التسويق | C16: 0
B17: تكاليف الرواتب والأجور | C17: 0
B18: مصاريف إدارية وعمومية | C18: 0
B19: تكاليف التمويل | C19: =T_Murabaha+T_LoanFeeOut
B20: تكاليف ورسوم أخرى (تصاميم، إشراف، رسوم حكومية، تسويق - مجمعة) | C20: =IndirectCost
B21: إجمالي التكاليف الإنشائية والفنية | C21: =SUM(C11:C20)
B22: الزكاة / الضريبة | C22: =T_Zakat
B23: صافي الربح | C23: =T_NetProfit
B24: * الملف الأصلي يجمع مصاريف الاستشاري والتصميم والإشراف والتسويق والرسوم في بند واحد (2%) - يلزم التفصيل.
B26: مؤشرات التقييم / الجدوى
B27: تكاليف الأرض (ريال) | C27: =LandCost
B28: تكاليف التطوير (ريال) | C28: =DevCost
B29: معدل العائد على الاستثمار (ROI) - سنوي | C29: =ROI
B30: معدل العائد الداخلي - العائد على التطوير (IRR) | C30: =IRR
B32: ملخص الدراسة التمهيدية والتسويقية
B33: الملخص
B34: ملخص الدراسة الفنية
B35: ="مشروع شقق سكنية على أرض مساحتها "&TEXT(LandArea,"#,##0")&" م2، بمسطحات بناء "&TEXT(BUA,"#,##0")&" م2 على "&TEXT(Floors,"0.0")&" أدوار تقريباً، ومساحة صافية للبيع "&TEXT(NetArea,"#,##0")&" م2 ("&TEXT(Units,"0")&" وحدة تقريباً بمتوسط "&TEXT(UnitArea,"0")&" م2)، مع قبو مواقف بمساحة "&TEXT(BasementArea,"#,##0")&" م2."
B37: الفترة الزمنية للتطوير والفحص والتسليم
B38: بداية المشروع | C38: =IF(StartDate="","",StartDate)
B39: مدة تنفيذ المشروع (شهر) | C39: =Months
B40: نهاية المشروع | C40: =IF(EndDate="","",EndDate)

Sheet الدراسة التسويقية
B1: الدراسة التمهيدية والتسويقية
B2: الخلايا الصفراء بيانات نوعية مطلوبة من العميل
B4: نبذة عامة للمشروع
B5: وصف فكرة المشروع | C5: ="تطوير "&TEXT(Units,"0")&" شقة سكنية تقريباً بمتوسط مساحة "&UnitArea&" م2 في حي "&District&" وبيعها على الخارطة خلال "&Months&" شهراً."
B6: المطور العقاري | C6: =IF(Developer="","",Developer)
B7: نوع وعدد ومساحات الوحدات السكنية | C7: ="شقق سكنية - "&TEXT(Units,"0.0")&" وحدة - متوسط "&UnitArea&" م2"
B8: المستشار الهندسي الرئيسي | C8: =IF(Consultant="","",Consultant)
B9: المحاسب القانوني (إذا انطبق) | C9: =IF(Auditor="","",Auditor)
B11: حجم القطاع العقاري - مساهمة القطاع في الناتج المحلي (آخر 3 سنوات)
B12: الفئة / السنة | C12: 2023 قيمة الناتج | D12: % من الناتج | E12: معدل النمو | F12: 2024 قيمة الناتج | G12: % من الناتج | H12: معدل النمو
B13: الأنشطة العقارية
B14: الناتج المحلي الإجمالي
B15: نبذة عن الوضع الحالي والتطورات المستقبلية للقطاع
B17: العملاء المستهدفين
B18: شرائح العملاء
B19: قنوات الوصول للعملاء
B20: العلاقات مع العملاء
B22: المشاريع المنافسة
B23: اسم المشروع | C23: المساحة (م2) | D23: نوع الوحدات | E23: عدد الوحدات | F23: متوسط سعر المتر | G23: الموقع | H23: المطور
B30: التحليل الرباعي (SWOT)
B31: نقاط القوة
B32: نقاط الضعف
B33: الفرص
B34: التهديدات
B36: المزيج التسويقي
B37: الخدمات / المنتجات | C37: ="شقق سكنية بمتوسط مساحة "&UnitArea&" م2 مع مواقف في القبو"
B38: التسعير | C38: ="متوسط سعر المتر "&TEXT('المدخلات'!E51,"#,##0")&" ريال في المرحلة الأولى و"&TEXT('المدخلات'!F51,"#,##0")&" ريال في المرحلة الثانية (متوسط "&TEXT('الحسابات'!C34,"#,##0")&" ريال)"
B39: الترويج
B40: التوزيع

Sheet الدراسة الفنية
B1: الدراسة الفنية
B4: تحليل الموقع
B5: موقع المشروع (حي - مدينة) | C5: =District&" - "&City
B6: الشوارع الرئيسية | C6: =IF(Streets="","",Streets)
B7: نطاق الموقع | C7: =IF(UrbanScope="","",UrbanScope)
B8: المساحة (وفقاً للصك) م2 | C8: =LandArea
B9: رقم الصك | C9: =IF(DeedNo="","",DeedNo)
B10: الاستخدامات | C10: =LandUse
B11: المساحة السكنية م2 | C11: =BUA
B12: المساحة التجارية م2 | C12: 0
B13: المساحة السكنية التجارية م2 | C13: 0
B14: نبذة عن موقع المشروع وإحداثياته (خريطة)
B16: التوزيع المساحي
B17: البيان | C17: المساحة (م2) | D17: النسبة من الأرض
B18: مساحة المخطط بالكامل (الأرض) | C18: =LandArea | D18: =IFERROR(C18/LandArea,0)
B19: المساحة المبنى عليها (الأرضي) | C19: =Footprint | D19: =IFERROR(C19/LandArea,0)
B20: المسطحات البنائية فوق الأرض | C20: =BUA | D20: =IFERROR(C20/LandArea,0)
B21: المساحة الصافية القابلة للبيع | C21: =NetArea | D21: =IFERROR(C21/LandArea,0)
B22: مساحة القبو (مواقف) | C22: =BasementArea | D22: =IFERROR(C22/LandArea,0)
B23: عدد الأدوار | C23: =Floors
B24: عدد أدوار القبو | C24: =BasementFloors
B25: عدد المواقف المطلوبة | C25: =Parking
B27: نبذة عن الوحدات العقارية
B28: نوع الوحدات | C28: متوسط المساحة م2 | D28: عدد الوحدات | E28: متوسط سعر التعاقد (ريال) | F28: تاريخ التسليم المتوقع
B29: شقق سكنية - السنة الأولى | C29: =UnitArea | D29: ='الحسابات'!E33 | E29: ='الحسابات'!E35 | F29: =IF(HandoverDate="","",HandoverDate)
B30: شقق سكنية - السنة الثانية | C30: =UnitArea | D30: ='الحسابات'!F33 | E30: ='الحسابات'!F35 | F30: =IF(HandoverDate="","",HandoverDate)
B32: المدة الزمنية
B33: التاريخ المتوقع لبداية المشروع | C33: =IF(StartDate="","",StartDate)
B34: التاريخ المتوقع لانتهاء المشروع | C34: =IF(EndDate="","",EndDate)
B35: التاريخ المتوقع لتسليم الوحدات | C35: =IF(HandoverDate="","",HandoverDate)
B36: مدة المشروع (شهر) | C36: =Months
B38: عناصر التكاليف الاستثمارية
B39: تكاليف الأرض | C39: المساحة م2 | D39: سعر المتر | E39: القيمة الإجمالية
B40: قيمة شراء الأرض | C40: =LandArea | D40: =LandPrice | E40: =LandPurchase
B41: السعي والضريبة | D41: =LandFeeRate | E41: =LandFees
B42: إجمالي تكاليف الأرض | C42: =LandArea | D42: =IFERROR(LandCost/LandArea,0) | E42: =LandCost
B44: التكاليف الإنشائية | C44: المساحة م2 | D44: تكلفة الإنشاء بالمتر | E44: القيمة الإجمالية
B45: تكاليف المباني والإنشاءات | C45: =BUA | D45: =ResCostM2 | E45: =ResCost
B46: تكاليف البنية التحتية والمرافق (القبو والمواقف) | C46: =BasementArea | D46: =BasementCostM2 | E46: =BasementCost
B47: القيمة الإجمالية لتكاليف الإنشاءات | C47: =BUA+BasementArea | D47: =IFERROR(DirectCost/(BUA+BasementArea),0) | E47: =DirectCost
...

Sheet الدراسة المالية
B1: الدراسة المالية
B4: الإيرادات المتوقعة
B5: نوع الوحدة | C5: المساحة المباعة م2 | D5: عدد الوحدات | E5: متوسط سعر المتر | F5: متوسط سعر الوحدة | G5: القيمة الإجمالية
B6: الوحدات السكنية - السنة الأولى | C6: ='الحسابات'!E32 | D6: ='الحسابات'!E33 | E6: ='الحسابات'!E34 | F6: ='الحسابات'!E35 | G6: ='الحسابات'!E36
B7: الوحدات السكنية - السنة الثانية | C7: ='الحسابات'!F32 | D7: ='الحسابات'!F33 | E7: ='الحسابات'!F34 | F7: ='الحسابات'!F35 | G7: ='الحسابات'!F36
B8: الوحدات السكنية - السنة الثالثة | C8: ='الحسابات'!G32 | D8: ='الحسابات'!G33 | E8: ='الحسابات'!G34 | F8: ='الحسابات'!G35 | G8: ='الحسابات'!G36
B9: إجمالي قيمة الإيرادات المتوقعة | C9: ='الحسابات'!C32 | D9: ='الحسابات'!C33 | E9: ='الحسابات'!C34 | F9: ='الحسابات'!C35 | G9: ='الحسابات'!C36
B11: الهيكل التمويلي
B12: العناصر | C12: القيمة الإجمالية | D12: النسبة المئوية | E12: المرحلة | F12: عدد الدفعات
B13: حقوق الملكية (الملاك / المساهمين) | C13: =T_Equity | D13: =IFERROR(C13/C16,0) | E13: فترة التجهيزات (شراء الأرض) | F13: =COUNTIF('الحسابات'!D69:G69,">0")
B14: قروض (التمويل البنكي) | C14: =LoanAmount | D14: =IFERROR(C14/C16,0) | E14: السنة الأولى والثانية | F14: =COUNTIF('المدخلات'!D52:G52,">0")
B15: مشترين (متحصلات البيع على الخارطة) | C15: =BuyersFund | D15: =IFERROR(C15/C16,0) | E15: خلال فترة البناء
B16: إجمالي التمويل | C16: =SUM(C13:C15) | D16: =SUM(D13:D15)
B18: قائمة الدخل (الأرباح والخسائر)
B19: البند | C19: فترة التجهيزات | D19: السنة الأولى | E19: السنة الثانية | F19: السنة الثالثة | G19: الإجمالي
B20: إجمالي الإيرادات | C20: ='الحسابات'!D36 | D20: ='الحسابات'!E36 | E20: ='الحسابات'!F36 | F20: ='الحسابات'!G36 | G20: ='الحسابات'!C36
B21: تكاليف الأرض | C21: =-'الحسابات'!D53 | D21: =-'الحسابات'!E53 | E21: =-'الحسابات'!F53 | F21: =-'الحسابات'!G53 | G21: =-'الحسابات'!C53
B22: تكاليف المباني والإنشاءات | C22: =-'الحسابات'!D54 | D22: =-'الحسابات'!E54 | E22: =-'الحسابات'!F54 | F22: =-'الحسابات'!G54 | G22: =-'الحسابات'!C54
B23: تكاليف البنية التحتية والمرافق | C23: =-'الحسابات'!D55 | D23: =-'الحسابات'!E55 | E23: =-'الحسابات'!F55 | F23: =-'الحسابات'!G55 | G23: =-'الحسابات'!C55
B24: مجمل الربح | C24: ='الحسابات'!D56 | D24: ='الحسابات'!E56 | E24: ='الحسابات'!F56 | F24: ='الحسابات'!G56 | G24: ='الحسابات'!C56
B25: تكاليف أخرى (تصاميم، إشراف، رسوم حكومية، تسويق) | C25: =-'الحسابات'!D57 | D25: =-'الحسابات'!E57 | E25: =-'الحسابات'!F57 | F25: =-'الحسابات'!G57 | G25: =-'الحسابات'!C57
B26: الاحتياطي وأتعاب المطور | C26: =-'الحسابات'!D58 | D26: =-'الحسابات'!E58 | E26: =-'الحسابات'!F58 | F26: =-'الحسابات'!G58 | G26: =-'الحسابات'!C58
B27: صافي الربح قبل رسوم التمويل والزكاة | C27: ='الحسابات'!D59 | D27: ='الحسابات'!E59 | E27: ='الحسابات'!F59 | F27: ='الحسابات'!G59 | G27: ='الحسابات'!C59
B28: رسوم التمويل | C28: =-'الحسابات'!D60 | D28: =-'الحسابات'!E60 | E28: =-'الحسابات'!F60 | F28: =-'الحسابات'!G60 | G28: =-'الحسابات'!C60
B29: صافي الربح قبل الزكاة أو الضريبة | C29: ='الحسابات'!D61 | D29: ='الحسابات'!E61 | E29: ='الحسابات'!F61 | F29: ='الحسابات'!G61 | G29: ='الحسابات'!C61
B30: الزكاة أو الضريبة | C30: =-'الحسابات'!D62 | D30: =-'الحسابات'!E62 | E30: =-'الحسابات'!F62 | F30: =-'الحسابات'!G62 | G30: =-'الحسابات'!C62
B31: صافي الربح أو الخسارة | C31: ='الحسابات'!D63 | D31: ='الحسابات'!E63 | E31: ='الحسابات'!F63 | F31: ='الحسابات'!G63 | G31: ='الحسابات'!C63
B32: نسبة صافي الربح أو الخسارة | C32: =IFERROR('الحسابات'!D63/'الحسابات'!D36,0) | D32: =IFERROR('الحسابات'!E63/'الحسابات'!E36,0) | E32: =IFERROR('الحسابات'!F63/'الحسابات'!F36,0) | F32: =IFERROR('الحسابات'!G63/'الحسابات'!G36,0) | G32: =IFERROR('الحسابات'!C63/'الحسابات'!C36,0)
B33: * الإيراد يُعترف به في سنة البيع، وتُحمّل تكاليف الأرض والبناء بنسبة المبيعات (مبدأ المقابلة)؛ تكاليف التمويل حسب حدوثها.
B35: قائمة التدفقات النقدية
B36: البند | C36: فترة التجهيزات | D36: السنة الأولى | E36: السنة الثانية | F36: السنة الثالثة | G36: الإجمالي
B37: التدفقات النقدية الداخلة
B38: المبيعات - الوحدات السكنية | C38: ='الحسابات'!D36 | D38: ='الحسابات'!E36 | E38: ='الحسابات'!F36 | F38: ='الحسابات'!G36 | G38: ='الحسابات'!C36
B39: إجمالي التدفقات النقدية الداخلة | C39: ='الحسابات'!D36 | D39: ='الحسابات'!E36 | E39: ='الحسابات'!F36 | F39: ='الحسابات'!G36 | G39: ='الحسابات'!C36
B40: التدفقات النقدية الخارجة
B41: تكاليف الأرض | C41: =-'الحسابات'!D38 | D41: =-'الحسابات'!E38 | E41: =-'الحسابات'!F38 | F41: =-'الحسابات'!G38 | G41: =-'الحسابات'!C38
B42: تكاليف المباني والإنشاءات | C42: =-'الحسابات'!D39 | D42: =-'الحسابات'!E39 | E42: =-'الحسابات'!F39 | F42: =-'الحسابات'!G39 | G42: =-'الحسابات'!C39
B43: تكاليف البنية التحتية والمرافق | C43: =-'الحسابات'!D40 | D43: =-'الحسابات'!E40 | E43: =-'الحسابات'!F40 | F43: =-'الحسابات'!G40 | G43: =-'الحسابات'!C40
B44: تكاليف أخرى (تصاميم، إشراف، رسوم حكومية، تسويق) | C44: =-'الحسابات'!D41 | D44: =-'الحسابات'!E41 | E44: =-'الحسابات'!F41 | F44: =-'الحسابات'!G41 | G44: =-'الحسابات'!C41
B45: الاحتياطي وأتعاب المطور | C45: ='الحسابات'!D42*-1-'الحسابات'!D43 | D45: ='الحسابات'!E42*-1-'الحسابات'!E43 | E45: ='الحسابات'!F42*-1-'الحسابات'!F43 | F45: ='الحسابات'!G42*-1-'الحسابات'!G43 | G45: ='الحسابات'!C42*-1-'الحسابات'!C43
...

Sheet النتائج والتوصيات
B1: نتائج وتوصيات الدراسة
B4: النتائج التقديرية للمشروع
B5: البند | C5: القيمة
B6: إجمالي الإيرادات - القيمة الإجمالية للإيرادات المتوقعة (ريال) | C6: =T_Revenue
B7: إجمالي التكاليف - القيمة الإجمالية للتكاليف (ريال) | C7: =TotalInvest+T_Zakat
B8: صافي الأرباح - القيمة الإجمالية لصافي الأرباح (ريال) | C8: =T_NetProfit
B9: رأس مال الملاك المطلوب (ريال) | C9: =T_Equity
B10: العائد الكلي على رأس المال | C10: =ROI_Total
B11: معدل العائد على الاستثمار ROI (سنوي) | C11: =ROI
B12: معدل العائد الداخلي IRR (التطوير)* | C12: =IRR
B13: هامش صافي الربح من المبيعات | C13: =MarginSales
B14: متوسط تكلفة الوحدة (ريال) | C14: =CostPerUnit
B15: متوسط سعر بيع الوحدة (ريال) | C15: ='الحسابات'!C35
B16: نسبة المرابحة البنكية (للمقارنة) | C16: =MurabahaRate
B17: * يقارن معدل العائد الداخلي بسعر الفائدة السائد (مع افتراض ثبات باقي العوامل الأخرى).
B19: التوصيات
B20: =IF(IRR>MurabahaRate,"المشروع مجدٍ مالياً: معدل العائد الداخلي ("&TEXT(IRR,"0.0%")&") أعلى من تكلفة التمويل ("&TEXT(MurabahaRate,"0.0%")&")، وصافي الربح المتوقع "&TEXT(T_NetProfit,"#,##0")&" ريال بعائد سنوي "&TEXT(ROI,"0.0%")&" على رأس مال الملاك.","المشروع غير مجدٍ بالافتراضات الحالية: معدل العائد الداخلي أقل من تكلفة التمويل.")
B21: التوصيات السوقية
B22: التوصيات الفنية
B23: التوصيات المالية

Sheet المدخلات
B1: المدخلات والافتراضات
B2: المصدر: نموذج ارض العليا - بتاريخ 11-08-2026 | الأزرق = مدخل رقمي، الأصفر = مطلوب من العميل
B4: أولاً | بيانات المشروع (نصية)
B5: اسم المشروع | C5: مشروع أرض العليا - شقق سكنية
B6: عنوان الدراسة | C6: دراسة جدوى مشروع شقق سكنية للبيع على الخارطة
B7: المدينة
B8: الحي | C8: العليا
B9: الشوارع الرئيسية
B10: رقم الصك
B11: نطاق الموقع
B12: الاستخدامات | C12: سكني
B13: المطور العقاري
B14: المستشار الهندسي الرئيسي
B15: المحاسب القانوني
B16: التاريخ المتوقع لبداية المشروع
B17: التاريخ المتوقع لانتهاء المشروع
B18: التاريخ المتوقع لتسليم الوحدات
B20: ثانياً | الافتراضات الرقمية
B21: وصف المشروع والمساحات
B22: مساحة أرض المشروع (م2) | C22: 3000
B23: نسبة البناء على الأرض | C23: 0.5
B24: معامل البناء | C24: 2.3716667
B25: نسبة المساحة الصافية (القابلة للبيع) | C25: 0.85
B26: متوسط مساحة الوحدة (م2) | C26: 250
B27: متطلبات المواقف لكل وحدة | C27: 5
B28: متوسط مساحة الموقف بالقبو (م2) | C28: 25
B29: تكاليف الأرض
B30: سعر شراء متر الأرض (ريال) | C30: 3200
B31: السعي والضريبة (% من قيمة الأرض) | C31: 0.075
B32: تكاليف البناء
B33: تكلفة بناء المتر - السكني (ريال) | C33: 1500
B34: تكلفة بناء المتر - القبو والمواقف (ريال) | C34: 600
B35: التكاليف الأخرى: تصاميم، إشراف، رسوم حكومية، تسويق (% من التكاليف المباشرة) | C35: 0.02
B36: الاحتياطي (% من التكاليف المباشرة) | C36: 0
B37: أتعاب المطور (% من التكاليف المباشرة) | C37: 0
B38: التمويل البنكي
B39: مبلغ التمويل البنكي (ريال) | C39: 8700000
B40: نسبة المرابحة السنوية | C40: 0.07
B41: رسوم ترتيب التمويل | C41: 0.01
B42: أخرى
...

Sheet الحسابات
B1: الحسابات التفصيلية
B2: لا تحتوي على مدخلات - كل الخلايا معادلات مرتبطة بورقة المدخلات
B4: أولاً | الحسابات الأساسية
B5: المساحات
B6: المساحة المبنى عليها (م2) | C6: =LandArea*BuildRatio
B7: المسطحات البنائية (م2) | C7: =LandArea*FAR
B8: عدد الأدوار | C8: =IFERROR(BUA/Footprint,0)
B9: المساحات الصافية القابلة للبيع (م2) | C9: =BUA*NetRatio
B10: عدد الوحدات | C10: =IFERROR(NetArea/UnitArea,0)
B11: عدد المواقف المطلوبة | C11: =Units*ParkPerUnit
B12: مساحة القبو - مواقف (م2) | C12: =Parking*ParkArea
B13: عدد أدوار القبو | C13: =IFERROR(BasementArea/LandArea,0)
B14: التكاليف
B15: قيمة شراء الأرض | C15: =LandArea*LandPrice
B16: السعي والضريبة | C16: =LandPurchase*LandFeeRate
B17: إجمالي تكلفة الأرض | C17: =LandPurchase+LandFees
B18: تكاليف المباني والإنشاءات (السكني) | C18: =BUA*ResCostM2
B19: تكاليف البنية التحتية والمرافق (القبو والمواقف) | C19: =BasementArea*BasementCostM2
B20: التكاليف المباشرة | C20: =ResCost+BasementCost
B21: التكاليف الأخرى (تصاميم، إشراف، رسوم حكومية، تسويق) | C21: =DirectCost*OtherCostRate
B22: الاحتياطي | C22: =DirectCost*ContRate
B23: أتعاب المطور | C23: =DirectCost*DevFeeRate
B24: التكاليف غير المباشرة | C24: =OtherCost+ContCost+DevFee
B25: إجمالي تكاليف التطوير (بدون الأرض) | C25: =DirectCost+IndirectCost
B26: إجمالي تكلفة المشروع (قبل التمويل) | C26: =LandCost+DevCost
B27: رسوم ترتيب التمويل | C27: =LoanAmount*LoanFeeRate
B29: ثانياً | الحسابات حسب الفترات
B30: البند | C30: الإجمالي | D30: فترة التجهيزات | E30: السنة الأولى | F30: السنة الثانية | G30: السنة الثالثة
B31: الإيرادات والتحصيل
B32: المساحات المباعة (م2) | C32: =SUM(D32:G32) | D32: ='المدخلات'!D50*NetArea | E32: ='المدخلات'!E50*NetArea | F32: ='المدخلات'!F50*NetArea | G32: ='المدخلات'!G50*NetArea
B33: عدد الوحدات المباعة | C33: =SUM(D33:G33) | D33: ='المدخلات'!D50*Units | E33: ='المدخلات'!E50*Units | F33: ='المدخلات'!F50*Units | G33: ='المدخلات'!G50*Units
B34: متوسط سعر المتر (ريال) | C34: =IFERROR(C36/C32,0) | D34: ='المدخلات'!D51 | E34: ='المدخلات'!E51 | F34: ='المدخلات'!F51 | G34: ='المدخلات'!G51
B35: متوسط سعر الوحدة (ريال) | C35: =C34*UnitArea | D35: =D34*UnitArea | E35: =E34*UnitArea | F35: =F34*UnitArea | G35: =G34*UnitArea
B36: إيرادات المبيعات | C36: =SUM(D36:G36) | D36: =D32*D34 | E36: =E32*E34 | F36: =F32*F34 | G36: =G32*G34
B37: التدفقات الخارجة
B38: تكاليف الأرض | C38: =SUM(D38:G38) | D38: ='المدخلات'!D48*LandCost | E38: ='المدخلات'!E48*LandCost | F38: ='المدخلات'!F48*LandCost | G38: ='المدخلات'!G48*LandCost
B39: تكاليف المباني والإنشاءات | C39: =SUM(D39:G39) | D39: ='المدخلات'!D49*ResCost | E39: ='المدخلات'!E49*ResCost | F39: ='المدخلات'!F49*ResCost | G39: ='المدخلات'!G49*ResCost
B40: تكاليف البنية التحتية والمرافق (القبو) | C40: =SUM(D40:G40) | D40: ='المدخلات'!D49*BasementCost | E40: ='المدخلات'!E49*BasementCost | F40: ='المدخلات'!F49*BasementCost | G40: ='المدخلات'!G49*BasementCost
B41: التكاليف الأخرى (تصاميم، إشراف، رسوم، تسويق) | C41: =SUM(D41:G41) | D41: ='المدخلات'!D49*OtherCost | E41: ='المدخلات'!E49*OtherCost | F41: ='المدخلات'!F49*OtherCost | G41: ='المدخلات'!G49*OtherCost
B42: الاحتياطي | C42: =SUM(D42:G42) | D42: ='المدخلات'!D49*ContCost | E42: ='المدخلات'!E49*ContCost | F42: ='المدخلات'!F49*ContCost | G42: ='المدخلات'!G49*ContCost
...
