Workbook
Name Units: 'المدخلات'!$C$5
Name UnitPrice: 'المدخلات'!$C$6
Name UnitArea: 'المدخلات'!$C$7
Name Months: 'المدخلات'!$C$8
Name DownPct: 'المدخلات'!$C$9
Name BuyCostRate: 'المدخلات'!$C$11
Name SellCostRate: 'المدخلات'!$C$12
Name DiscCons: 'المدخلات'!$C$14
Name DiscBase: 'المدخلات'!$C$15
Name DiscOpt: 'المدخلات'!$C$16
Name Rent: 'المدخلات'!$C$18
Name RentCostRate: 'المدخلات'!$C$19
Name BenchRate: 'المدخلات'!$C$21
Name MktAvgM2: 'المشاريع المحيطة'!$F$15
Name MktMedM2: 'المشاريع المحيطة'!$F$16
Name MktAvgUnit: 'المشاريع المحيطة'!$F$17
Name OurPriceM2: 'الحسابات'!$C$4
Name DealValue: 'الحسابات'!$C$5
Name BuyCosts: 'الحسابات'!$C$6
Name TotalCost: 'الحسابات'!$C$7
Name Discount: 'الحسابات'!$C$8
Name MktValue: 'الحسابات'!$C$9
Name InstantEquity: 'الحسابات'!$C$10
Name CashIn: 'الحسابات'!$C$11
Name RentGross: 'الحسابات'!$C$28
Name RentNet: 'الحسابات'!$C$29
Name YieldGross: 'الحسابات'!$C$30
Name YieldNet: 'الحسابات'!$C$31
Name Payback: 'الحسابات'!$C$32
Name MktYield: 'الحسابات'!$C$33

Sheet عرض المستثمر
B1: فرصة استثمارية: 12 تاون هاوس - القادسية تون هاوس (شرق الرياض)
B2: دراسة جدوى مبسطة لشراء 12 وحدة بسعر جملة مقارنةً بأسعار السوق المحيط
B4: الصفقة المقترحة | G4: سعر المتر (ريال) | H4: القيمة
B5: عدد الوحدات | C5: =Units | G5: ='المشاريع المحيطة'!B6&" "&'المشاريع المحيطة'!D6&"م2" | H5: ='المشاريع المحيطة'!F6
B6: سعر الوحدة (ريال) | C6: =UnitPrice | G6: ='المشاريع المحيطة'!B7&" "&'المشاريع المحيطة'!D7&"م2" | H6: ='المشاريع المحيطة'!F7
B7: مساحة الوحدة (م2) | C7: =UnitArea | G7: ='المشاريع المحيطة'!B8&" "&'المشاريع المحيطة'!D8&"م2" | H7: ='المشاريع المحيطة'!F8
B8: قيمة الصفقة (ريال) | C8: =DealValue | G8: ='المشاريع المحيطة'!B9&" "&'المشاريع المحيطة'!D9&"م2" | H8: ='المشاريع المحيطة'!F9
B9: إجمالي التكلفة شاملة ضريبة التصرفات (ريال) | C9: =TotalCost | G9: ='المشاريع المحيطة'!B10&" "&'المشاريع المحيطة'!D10&"م2" | H9: ='المشاريع المحيطة'!F10
G10: ='المشاريع المحيطة'!B11&" "&'المشاريع المحيطة'!D11&"م2" | H10: ='المشاريع المحيطة'!F11
B11: لماذا هذه الصفقة؟ - مقارنة بالسوق | G11: ='المشاريع المحيطة'!B12&" "&'المشاريع المحيطة'!D12&"م2" | H11: ='المشاريع المحيطة'!F12
B12: سعر المتر لنا | C12: =OurPriceM2 | G12: مشروعنا | H12: =OurPriceM2
B13: متوسط سعر المتر للتاون هاوس في القادسية والجوار | C13: =MktAvgM2
B14: خصم سعرنا عن متوسط السوق | C14: =Discount
B15: القيمة السوقية للـ12 وحدة بمتوسط السوق | C15: =MktValue
B16: فرق القيمة لصالح المستثمر من يوم الشراء | C16: =InstantEquity
B18: الخيار (1): إعادة البيع عند التسليم
B19: البند | C19: متحفظ | D19: أساسي | E19: متفائل
B20: سعر بيع المتر | C20: ='الحسابات'!C15 | D20: ='الحسابات'!D15 | E20: ='الحسابات'!E15
B21: سعر بيع الوحدة | C21: ='الحسابات'!C16 | D21: ='الحسابات'!D16 | E21: ='الحسابات'!E16
B22: صافي متحصلات البيع | C22: ='الحسابات'!C19 | D22: ='الحسابات'!D19 | E22: ='الحسابات'!E19
B23: صافي الربح | C23: ='الحسابات'!C20 | D23: ='الحسابات'!D20 | E23: ='الحسابات'!E20
B24: العائد الكلي | C24: ='الحسابات'!C21 | D24: ='الحسابات'!D21 | E24: ='الحسابات'!E21
B25: العائد السنوي | C25: ='الحسابات'!C22 | D25: ='الحسابات'!D22 | E25: ='الحسابات'!E22
B26: العائد السنوي على النقد المدفوع فعلياً | C26: ='الحسابات'!C24 | D26: ='الحسابات'!D24 | E26: ='الحسابات'!E24
B27: ="سعر التعادل: "&TEXT('الحسابات'!C25,"#,##0")&" ريال/م2 - أي أن السوق يجب أن ينخفض "&TEXT(1-'الحسابات'!C25/MktAvgM2,"0%")&" عن متوسطه الحالي حتى يخسر المستثمر."
B29: أثر شروط الصفقة على العائد السنوي (السيناريو الأساسي)
B30: نسبة الدفع عند التعاقد | C30: المستثمر يتحمل الضريبة | D30: المطور يتحمل الضريبة
B31: 1 | C31: =(1+('الحسابات'!D19-DealValue*(1+BuyCostRate))/(DealValue*1+DealValue*BuyCostRate))^(12/Months)-1 | D31: =(1+('الحسابات'!D19-DealValue*(1+0))/(DealValue*1+DealValue*0))^(12/Months)-1
B32: 0.5 | C32: =(1+('الحسابات'!D19-DealValue*(1+BuyCostRate))/(DealValue*0.5+DealValue*BuyCostRate))^(12/Months)-1 | D32: =(1+('الحسابات'!D19-DealValue*(1+0))/(DealValue*0.5+DealValue*0))^(12/Months)-1
B33: 0.3 | C33: =(1+('الحسابات'!D19-DealValue*(1+BuyCostRate))/(DealValue*0.3+DealValue*BuyCostRate))^(12/Months)-1 | D33: =(1+('الحسابات'!D19-DealValue*(1+0))/(DealValue*0.3+DealValue*0))^(12/Months)-1
B34: الدفع على مراحل (الباقي عند التسليم) وتحمّل المطور للضريبة يرفعان عائد المستثمر على النقد المدفوع بشكل كبير.
B36: الخيار (2): الاحتفاظ والتأجير
B37: الإيجار السنوي المتوقع للوحدة | C37: =Rent
B38: صافي الإيجار السنوي (12 وحدة) | C38: =RentNet
B39: العائد الإيجاري الصافي على سعرنا | C39: =YieldNet
B40: العائد الإيجاري لو اشترى بسعر السوق | C40: =MktYield
B41: عائد بديل (ودائع / صكوك) | C41: =BenchRate
B42: فترة الاسترداد من الإيجار (سنة) | C42: =Payback
B44: نقاط القوة للمستثمر
B45: ="سعر جملة "&TEXT(OurPriceM2,"#,##0")&" ريال/م2 مقابل متوسط "&TEXT(MktAvgM2,"#,##0")&" ريال/م2 في السوق المحيط (خصم "&TEXT(Discount,"0%")&")."
...

Sheet المشاريع المحيطة
B1: أسعار التاون هاوس في القادسية والأحياء المجاورة (شرق الرياض)
B2: عروض معلنة على المنصات العقارية (أسعار طلب وليست صفقات منفذة) - تم البحث في سبتمبر 2026
B4: أولاً | عروض بيع تاون هاوس (مساحة معلنة)
B5: الحي | C5: الوصف | D5: المساحة م2 | E5: السعر (ريال) | F5: سعر المتر | G5: سعرنا أقل بـ | H5: المصدر
B6: القادسية | C6: تاون هاوس | D6: 200 | E6: 950900 | F6: =E6/D6 | G6: =1-OurPriceM2/F6 | H6: حراج
B7: القادسية | C7: فيلا تاون هاوس | D7: 220 | E7: 1200000 | F7: =E7/D7 | G7: =1-OurPriceM2/F7 | H7: حراج
B8: القادسية | C8: تاون هاوس 3 أدوار - عمر سنتين | D8: 188 | E8: 1300000 | F8: =E8/D8 | G8: =1-OurPriceM2/F8 | H8: حراج
B9: اليرموك | C9: تاون هاوس فاخر 4 غرف | D9: 251.51 | E9: 1800000 | F9: =E9/D9 | G9: =1-OurPriceM2/F9 | H9: حراج
B10: اليرموك | C10: تاون هاوس | D10: 253.5 | E10: 1550000 | F10: =E10/D10 | G10: =1-OurPriceM2/F10 | H10: بروبرتي فايندر
B11: النهضة | C11: تاون هاوس | D11: 264 | E11: 1500000 | F11: =E11/D11 | G11: =1-OurPriceM2/F11 | H11: عقار
B12: النهضة | C12: تاون هاوس علوي | D12: 180 | E12: 1200000 | F12: =E12/D12 | G12: =1-OurPriceM2/F12 | H12: عقار
B13: مشروعنا - القادسية تون هاوس | C13: تاون هاوس جديد - بيع بالجملة 12 وحدة | D13: =UnitArea | E13: =UnitPrice | F13: =OurPriceM2
B15: متوسط سعر المتر في السوق | F15: =AVERAGE(F6:F12)
B16: وسيط سعر المتر في السوق | F16: =MEDIAN(F6:F12)
B17: متوسط سعر الوحدة المعروضة | F17: =AVERAGE(E6:E12)
B19: ثانياً | عروض أخرى في الحي (بدون مساحة معلنة / للمقارنة)
B20: الحي | C20: الوصف | D20: المساحة م2 | E20: السعر (ريال) | H20: المصدر
B21: القادسية | C21: تاون هاوس علوي | D21: - | E21: 1200000 | H21: حراج
B22: القادسية | C22: تاون هاوس أرضي | D22: - | E22: 1500000 | H22: حراج
B23: القادسية | C23: تاون هاوس علوي | D23: - | E23: 1400000 | H23: حراج
B24: اليرموك | C24: دور تاون هاوس أرضي | D24: - | E24: 1750000 | H24: حراج
B25: القادسية | C25: شقة - مشروع ركايا (ركز) | D25: 181 | E25: 956000 | H25: ركز
B26: القادسية | C26: شقة / بنتهاوس - مشروع نورفا (ركز) | D26: 273 | E26: 1125000 | H26: ركز
B27: ملاحظة: شقق مشروع نورفا في نفس الحي تبدأ من 1,125,000 ريال - أي أن سعر التاون هاوس عندنا قريب من سعر الشقة.
B29: ثالثاً | إيجارات التاون هاوس في القادسية
B30: الحي | C30: الوصف | D30: المساحة م2 | E30: الإيجار السنوي | H30: المصدر
B31: القادسية | C31: تاون هاوس دورين - مجمع ركايا (دفعة واحدة) | D31: 173 | E31: 75000 | H31: حراج
B32: القادسية | C32: تاون هاوس دورين - مجمع ركايا (دفعتين) | D32: 173 | E32: 85000 | H32: حراج
B33: القادسية | C33: تاون هاوس دورين 3 غرف | D33: 189 | E33: - | H33: عقار (X)
B34: القادسية | C34: تاون هاوس (دفعة واحدة) | D34: - | E34: 72000 | H34: حراج

Sheet الحسابات
B1: الحسابات
B3: الصفقة
B4: سعر المتر للمستثمر | C4: =UnitPrice/UnitArea
B5: قيمة الصفقة (12 وحدة) | C5: =Units*UnitPrice
B6: تكاليف الشراء | C6: =DealValue*BuyCostRate
B7: إجمالي تكلفة المستثمر | C7: =DealValue+BuyCosts
B8: خصم سعرنا عن متوسط السوق | C8: =1-OurPriceM2/MktAvgM2
B9: القيمة السوقية للوحدات بمتوسط السوق | C9: =Units*UnitArea*MktAvgM2
B10: فرق القيمة لصالح المستثمر يوم الشراء | C10: =MktValue-DealValue
B11: النقد المستثمر فعلياً حتى التسليم (دفعة التعاقد + تكاليف الشراء) | C11: =DealValue*DownPct+BuyCosts
B13: سيناريوهات إعادة البيع عند التسليم
B14: البند | C14: متحفظ | D14: أساسي | E14: متفائل
B15: سعر بيع المتر | C15: =MktAvgM2*(1-DiscCons) | D15: =MktAvgM2*(1-DiscBase) | E15: =MktAvgM2*(1-DiscOpt)
B16: سعر بيع الوحدة | C16: =C15*UnitArea | D16: =D15*UnitArea | E16: =E15*UnitArea
B17: إجمالي المبيعات (12 وحدة) | C17: =C16*Units | D17: =D16*Units | E17: =E16*Units
B18: تكاليف البيع | C18: =C17*SellCostRate | D18: =D17*SellCostRate | E18: =E17*SellCostRate
B19: صافي المتحصلات | C19: =C17-C18 | D19: =D17-D18 | E19: =E17-E18
B20: صافي الربح | C20: =C19-TotalCost | D20: =D19-TotalCost | E20: =E19-TotalCost
B21: العائد الكلي على إجمالي التكلفة | C21: =C20/TotalCost | D21: =D20/TotalCost | E21: =E20/TotalCost
B22: العائد السنوي المركب | C22: =(1+C21)^(12/Months)-1 | D22: =(1+D21)^(12/Months)-1 | E22: =(1+E21)^(12/Months)-1
B23: العائد على النقد المستثمر فعلياً (حسب نسبة الدفع المقدم) | C23: =C20/CashIn | D23: =D20/CashIn | E23: =E20/CashIn
B24: العائد السنوي على النقد المستثمر | C24: =(1+C23)^(12/Months)-1 | D24: =(1+D23)^(12/Months)-1 | E24: =(1+E23)^(12/Months)-1
B25: سعر المتر اللازم للتعادل | C25: =TotalCost/(1-SellCostRate)/Units/UnitArea | D25: =TotalCost/(1-SellCostRate)/Units/UnitArea | E25: =TotalCost/(1-SellCostRate)/Units/UnitArea
B27: سيناريو التأجير
B28: إجمالي الإيجار السنوي (12 وحدة) | C28: =Rent*Units
B29: صافي الإيجار بعد المصاريف | C29: =RentGross*(1-RentCostRate)
B30: العائد الإيجاري الإجمالي | C30: =RentGross/TotalCost
B31: العائد الإيجاري الصافي | C31: =RentNet/TotalCost
B32: فترة استرداد رأس المال من الإيجار (سنة) | C32: =TotalCost/RentNet
B33: العائد الإيجاري لو اشترى بسعر السوق | C33: =RentNet/(MktValue*(1+BuyCostRate))

Sheet المدخلات
B1: المدخلات والافتراضات
B2: الأزرق = مدخل قابل للتعديل | الأصفر = افتراض يحتاج تأكيد
B4: الصفقة
B5: عدد الوحدات | C5: 12
B6: سعر الوحدة للمستثمر (ريال) | C6: 1150000
B7: مساحة الوحدة (م2) | C7: 250 | D7: افتراض من ملف القادسية (متوسط مساحة الوحدة 250 م2) - يرجى التأكيد
B8: مدة الاحتفاظ حتى التسليم وإعادة البيع (شهر) | C8: 22 | D8: مدة المشروع في ملف القادسية
B9: نسبة الدفع عند التعاقد (الباقي عند التسليم) | C9: 1 | D9: 100% = دفع كامل مقدم (أكثر تحفظاً)
B10: تكاليف الشراء والبيع
B11: تكاليف الشراء: ضريبة التصرفات العقارية | C11: 0.05 | D11: تُصفَّر لو تحملها المطور كحافز للصفقة
B12: تكاليف إعادة البيع: سعي / تسويق | C12: 0.025
B13: سيناريوهات إعادة البيع (خصم عن متوسط سعر المتر في السوق)
B14: المتحفظ | C14: 0.15 | D14: البيع بأقل 15% من متوسط السوق
B15: الأساسي | C15: 0.1 | D15: البيع بأقل 10% من متوسط السوق
B16: المتفائل | C16: 0 | D16: البيع بمتوسط السوق
B17: سيناريو التأجير
B18: الإيجار السنوي للوحدة (ريال) | C18: 85000 | D18: عروض القادسية 72-85 ألف لمساحة 173-189 م2؛ وحدتنا أكبر
B19: مصاريف التشغيل والصيانة والإدارة (% من الإيجار) | C19: 0.1
B20: للمقارنة
B21: عائد بديل (ودائع / صكوك) سنوياً | C21: 0.05
