Workbook

Sheet ملخص المستثمر
B2: فرصة استثمارية – 12 وحدة تاون هاوس | القادسية تاون هاوس (حصير) – شرق الرياض
B3: ملخص تنفيذي – كل الأرقام مرتبطة تلقائياً بباقي الأوراق
B5: العرض | E5: سعرنا مقابل تاون هاوس القادسية
B6: عدد الوحدات | C6: =الافتراضات!$C$7 -> 12 | E6: متوسط سعر التاون هاوس في القادسية | F6: ='المقارنات السعرية'!E30 -> 1300000
B7: سعر الوحدة للمستثمر | C7: =الافتراضات!$C$8 -> 1150000 | E7: أغلى تاون هاوس معروض في القادسية | F7: ='المقارنات السعرية'!F30 -> 1500000
B8: مساحة الوحدة (4 مستويات) م² | C8: =الافتراضات!$C$13 -> 273.64 | E8: وحدات القادسية المرصودة الأغلى من سعرنا | F8: ='المقارنات السعرية'!I34&" من "&'المقارنات السعرية'!D30 -> 7 من 7
B9: سعر المتر على إجمالي المساحة | C9: ='المقارنات السعرية'!J13 -> 4202.602 | E9: خصمنا عن متوسط سعر وحدة القادسية | F9: ='المقارنات السعرية'!I36 -> 0.11538462
B10: إجمالي قيمة الصفقة | C10: ='العائد على المستثمر'!C5 -> 13800000 | E10: متوسط مساحة تاون هاوس القادسية م² | F10: ='المقارنات السعرية'!G30 -> 235.14286
B11: إجمالي التكلفة شاملة ضريبة التصرفات | C11: ='العائد على المستثمر'!C7 -> 14490000 | E11: مكسب فوري مقابل سعر البيع للأفراد (12 وحدة) | F11: ='العائد على المستثمر'!C10 -> 2400000
B13: العائد – البيع بعد التسليم (سعر الأفراد) | E13: العائد – التأجير
B14: صافي الربح | C14: ='العائد على المستثمر'!C22 -> 495000 | E14: إيجار سنوي إجمالي (12 وحدة) | F14: ='العائد على المستثمر'!C42 -> 900000
B15: ROI الكلي | C15: ='العائد على المستثمر'!C23 -> 0.034161491 | E15: صافي الدخل السنوي | F15: ='العائد على المستثمر'!C44 -> 795150
B16: IRR السنوي | C16: ='العائد على المستثمر'!C25 -> 0.016937309 | E16: العائد الإيجاري الإجمالي | F16: ='العائد على المستثمر'!C45 -> 0.065217391
B17: صافي الربح لو تحمل المطور ضريبة الشراء | C17: ='العائد على المستثمر'!E34 -> 1185000 | E17: صافي العائد الإيجاري | F17: ='العائد على المستثمر'!C46 -> 0.054875776
B18: ROI لو تحمل المطور ضريبة الشراء | C18: ='العائد على المستثمر'!F34 -> 0.085869565 | E18: العائد الإيجاري لمن يشتري بمتوسط السوق | F18: ='العائد على المستثمر'!C47 -> 0.057692308
B20: لماذا هذه الصفقة؟
B21: ="• "&F8&" تاون هاوس في القادسية معروضة بأعلى من سعرنا، تصل إلى "&TEXT(F7,"#,##0")&" ريال – ومتوسط الحي "&TEXT(F6,"#,##0")&" ريال." -> • 7 من 7 تاون هاوس في القادسية معروضة بأعلى من سعرنا، تصل إلى 1,500,000 ريال – ومتوسط الحي 1,300,000 ريال.
B22: ="• وحدتنا "&TEXT(C8,"#,##0")&" م² على 4 مستويات مقابل متوسط "&TEXT(F10,"#,##0")&" م² في الحي – مساحة أكبر بسعر أقل." -> • وحدتنا 274 م² على 4 مستويات مقابل متوسط 235 م² في الحي – مساحة أكبر بسعر أقل.
B23: • مواصفات لا تتوفر في أغلب المعروض: مصعد خاص يخدم كل الأدوار، قبو بموقف سيارة خاص ومجلس، سطح وملحق خاص، 4 غرف نوم + غرفة خادمة، 5 دورات مياه.
B24: • وحدة كاملة مستقلة من القبو للسطح – وليست نظام أدوار (أرضي/علوي) مثل أغلب التاون هاوس المعروض.
B25: • موقع على بعد دقيقتين من طريق الشيخ جابر و5 دقائق من طريقي الأمير محمد بن سلمان والملك عبدالله و20 دقيقة من المطار.
B26: • المطور حصير: 311 وحدة منفذة وأكثر من 600 وحدة مستهدفة في 7 مشاريع.
B27: ="• للتأجير: عائد إجمالي "&TEXT(F16,"0.0%")&" على سعر الشراء مقابل "&TEXT(F18,"0.0%")&" لمن يشتري بمتوسط سعر الحي." -> • للتأجير: عائد إجمالي 6.5% على سعر الشراء مقابل 5.8% لمن يشتري بمتوسط سعر الحي.
B29: تنبيه: المقارنات أسعار عرض من منصات الإعلانات (بحث 30/9/2026) وليست صفقات منفذة، والعوائد تقديرية حسب الافتراضات المعلنة وليست ضماناً.

Sheet مزايا المشروع
B2: لماذا وحدتنا أفضل؟ – مقارنة المواصفات مع تاون هاوس القادسية المعروضة
B3: المواصفات من بروشور مشروع حصير – تاون هاوس القادسية، ومواصفات السوق من نصوص الإعلانات المرصودة في ورقة المقارنات
B5: الميزة | C5: وحدتنا (حصير) | D5: التاون هاوس المعروض في القادسية | E5: الأثر على المستثمر / المشتري
B6: نظام الوحدة | C6: وحدة كاملة مستقلة من القبو إلى السطح | D6: أغلبها أدوار (أرضي / علوي) يتقاسمان المبنى | E6: خصوصية كاملة وملكية مستقلة = سهولة بيع وتأجير لعائلة واحدة
B7: عدد المستويات | C7: 4 (قبو + أرضي + أول + ملحق وسطح) | D7: 2 – 3 أدوار | E7: مساحة معيشة أكبر بنفس السعر
B8: إجمالي المساحة | C8: =الافتراضات!$C$13 -> 273.64 | D8: ="متوسط "&TEXT('المقارنات السعرية'!G30,"#,##0")&" م²" -> متوسط 235 م² | E8: مساحة أكبر من متوسط القادسية
B9: مصعد خاص | C9: ✓ مصعد خاص يخدم جميع الأدوار | D9: غالباً "مؤسس" فقط أو للعلوي فقط | E9: ميزة نادرة تستهدف كبار السن والعائلات – تكلفة تركيبها لاحقاً على المشتري
B10: موقف السيارة | C10: ✓ موقف خاص داخل القبو | D10: موقف أمام المبنى / غير مذكور | E10: حماية للسيارة وخصوصية – ميزة تسويقية قوية
B11: مجلس / صالة ترفيهية بالقبو | C11: ✓ | D11: غير متوفر غالباً | E11: مساحة ضيافة إضافية دون التأثير على مساحة المعيشة
B12: غرف النوم | C12: 4 غرف (ماستر + 2 بالأول + غرفة بالملحق) + غرفة خادمة | D12: 3 – 4 غرف | E12: تناسب العائلات الكبيرة = طلب أعلى
B13: دورات المياه | C13: 5 دورات مياه | D13: 2 – 4 | E13: راحة أعلى وقيمة إيجارية أعلى
B14: سطح خاص | C14: ✓ سطح خاص مع ملحق | D14: متاح غالباً للعلوي فقط | E14: مساحة خارجية خاصة لكل وحدة
B15: التصميم | C15: واجهات مودرن وتشطيب حديث – مشروع جديد | D15: متفاوت، وبعضها مستعمل | E15: منتج جديد بضمانات المطور
B16: الموقع | C16: طريق الشيخ جابر: دقيقتان | الأمير محمد بن سلمان: 5 د | الملك عبدالله: 5 د | مطار الملك خالد: 20 د | D16: داخل الحي | E16: وصول سريع لأهم محاور الرياض
B17: المطور | C17: حصير للتطوير العقاري: 311 وحدة منفذة (2020–2023) و+600 وحدة مستهدفة في 7 مشاريع | D17: متفاوت – أغلب المعروض إعلانات أفراد ومكاتب | E17: مخاطر تنفيذ أقل وثقة أعلى للمشتري النهائي
B18: السعر | C18: =TEXT(الافتراضات!C8,"#,##0")&" ريال للوحدة" -> 1,150,000 ريال للوحدة | D18: =TEXT('المقارنات السعرية'!E30,"#,##0")&" متوسط – حتى "&TEXT('المقارنات السعرية'!F30,"#,##0") -> 1,300,000 متوسط – حتى 1,500,000 | E18: مواصفات أعلى بسعر أقل = هامش ربح عند إعادة البيع أو التأجير
B20: "غالباً" تعني حسب ما ورد في نصوص الإعلانات المرصودة، وقد تختلف بعض الوحدات.

Sheet الافتراضات
B2: الافتراضات – عرض شراء 12 وحدة تاون هاوس | القادسية تاون هاوس (حصير)
B3: الخلايا بالخط الأزرق والخلفية الصفراء مدخلات قابلة للتعديل – باقي النموذج يُحسب تلقائياً
B5: البند | C5: القيمة | D5: المصدر / ملاحظة
B6: أولاً | العرض والوحدة
B7: عدد الوحدات المعروضة | C7: 12 | D7: من طلب الإدارة
B8: سعر الوحدة للمستثمر (ريال) | C8: 1150000 | D8: من طلب الإدارة – سعر جملة لكامل الـ 12 وحدة
B9: مساحة القبو م² (مجلس + موقف خاص + مصعد) | C9: 71.4 | D9: بروشور المشروع – مخطط B1
B10: مساحة الدور الأرضي م² | C10: 75.33 | D10: بروشور المشروع – مخطط GF
B11: مساحة الدور الأول م² | C11: 75.33 | D11: بروشور المشروع – مخطط 1F
B12: مساحة الملحق / السطح م² | C12: 51.58 | D12: بروشور المشروع – مخطط RF
B13: إجمالي مساحة الوحدة م² | C13: =SUM(C9:C12) -> 273.64 | D13: إجمالي 273.64 م² حسب البروشور
B14: المساحة فوق الأرض (بدون القبو) م² | C14: =SUM(C10:C12) -> 202.24 | D14: للمقارنة العادلة مع وحدات السوق التي لا تحتوي قبو
B15: ثانياً | تكاليف الشراء
B16: ضريبة التصرفات العقارية عند الشراء | C16: 0.05 | D16: 5% نظاماً – ضعها 0% إذا تحملها المطور كحافز للمستثمر
B17: سعي / عمولة الشراء | C17: 0 | D17: شراء مباشر من المطور بدون وسيط
B18: ثالثاً | جدول السداد (كل فترة = 6 أشهر)
B19: الدفعة عند التوقيع (شهر 0) | C19: 1 | D19: افتراض تحفظي: سداد كامل مقدماً – التقسيط يرفع العائد
B20: الدفعة الثانية (شهر 6) | C20: 0
B21: الدفعة الثالثة (شهر 12) | C21: 0
B22: الدفعة الرابعة (شهر 18) | C22: 0
B23: الدفعة عند التسليم (شهر 24) | C23: 0
B24: رابعاً | سيناريو إعادة البيع بعد التسليم
B25: سعر بيع الوحدة للأفراد (ريال) | C25: 1350000 | D25: دراسة المشروع: 5,400 ريال/م² × 250 م² – ويقع ضمن نطاق عروض القادسية (1.2 – 1.5 مليون)
B26: خصم تحفظي على سعر البيع | C26: 0 | D26: عدّله لاختبار سيناريو متحفظ
B27: نمو سنوي في الأسعار حتى التسليم | C27: 0 | D27: افتراض تحفظي = صفر
B28: المدة حتى التسليم والبيع (سنة) | C28: 2 | D28: دراسة المشروع 22 شهراً – مقربة إلى سنتين
B29: سعر بيع الوحدة المتوقع عند الخروج (ريال) | C29: =C25*(1-C26)*(1+C27)^C28 -> 1350000 | D29: محسوب
B30: عمولة التسويق / السعي عند البيع | C30: 0.025 | D30: العرف السائد 2.5%
B31: ضريبة التصرفات عند إعادة البيع | C31: 0.05 | D31: 5% – تحفظياً على البائع
B32: خامساً | سيناريو الاحتفاظ والتأجير
B33: الإيجار السنوي للوحدة (ريال) | C33: 75000 | D33: تاون هاوس 173م² بمجمع ركايا – القادسية مؤجر بـ 75,000 (حراج) ووحدتنا أكبر وبمصعد
B34: نسبة الإشغال | C34: 0.95 | D34: افتراض
B35: مصاريف التشغيل والصيانة من الإيجار | C35: 0.07 | D35: افتراض (إدارة أملاك + صيانة)
B36: تحقق: مجموع جدول السداد = 100% | C36: =IF(ROUND(SUM(C19:C23),4)=1,"صحيح","خطأ") -> صحيح

Sheet المقارنات السعرية
B2: المقارنات السعرية – تاون هاوس حي القادسية فقط (شرق الرياض)
B3: أسعار عرض (طلب) من منصات الإعلانات – بحث بتاريخ 30 سبتمبر 2026 – حي القادسية فقط، مرتبة من الأغلى. ليست صفقات منفذة.
B5: # | C5: الحي | D5: الوصف | E5: نظام الوحدة | F5: مصعد | G5: قبو / موقف خاص | H5: المساحة م² | I5: السعر المعروض | J5: سعر المتر | K5: التاريخ | L5: المصدر
B6: 1 | C6: القادسية | D6: تاون هاوس أرضي على شارع 20 | E6: أرضي (أدوار) | F6: للعلوي فقط | G6: غير مذكور | H6: 300 | I6: 1500000 | J6: =IFERROR(I6/H6,0) -> 5000 | K6: 2026 | L6: https://haraj.com.sa/11140216303/
B7: 2 | C7: القادسية | D7: تاون هاوس علوي – نفس المبنى | E7: علوي (أدوار) | F7: ✓ | G7: غير مذكور | H7: 250 | I7: 1400000 | J7: =IFERROR(I7/H7,0) -> 5600 | K7: 2026 | L7: https://haraj.com.sa/11140216303/
B8: 3 | C8: القادسية | D8: تاون هاوس مودرن واجهة شرقية 4 غرف | E8: وحدة كاملة | F8: مؤسس فقط | G8: غير مذكور | H8: 248 | I8: 1350000 | J8: =IFERROR(I8/H8,0) -> 5443.5484 | K8: 2026 | L8: https://sa.aqar.fm/فلل-للبيع/الرياض/شرق-الرياض/حي-القادسية/تاون-هاوس
B9: 4 | C9: القادسية | D9: شقة تاون هاوس دوبلكس 3 أدوار | E9: دوبلكس | F9: غير مذكور | G9: غير مذكور | H9: 215 | I9: 1250000 | J9: =IFERROR(I9/H9,0) -> 5813.9535 | K9: 2026 | L9: https://www.bayut.sa/en/for-sale/villas/riyadh/east-riyadh/al-qadisiyah/
B10: 5 | C10: القادسية | D10: تاون هاوس علوي بمصعد وعداد مستقل | E10: علوي (أدوار) | F10: ✓ | G10: غير مذكور | H10: 225 | I10: 1200000 | J10: =IFERROR(I10/H10,0) -> 5333.3333 | K10: مارس 2026 | L10: https://haraj.com.sa/en/11164555558/
B11: 6 | C11: القادسية | D11: فيلا تاون هاوس | E11: غير محدد | F11: غير مذكور | G11: غير مذكور | H11: 220 | I11: 1200000 | J11: =IFERROR(I11/H11,0) -> 5454.5455 | K11: أغسطس 2025 | L11: https://haraj.com.sa/11151387860/
B12: 7 | C12: القادسية | D12: تاون هاوس – شارع 30 غرب، 3 غرف | E12: وحدة كاملة | F12: غير مذكور | G12: غير مذكور | H12: 188 | I12: 1200000 | J12: =IFERROR(I12/H12,0) -> 6382.9787 | K12: 2026 | L12: https://www.bayut.sa/en/property/details-87578604.html
B13: ★ | C13: القادسية | D13: مشروعنا – القادسية تاون هاوس (حصير) – سعر المستثمر | E13: وحدة كاملة مستقلة 4 مستويات | F13: ✓ يخدم كل الأدوار | G13: ✓ قبو + موقف خاص | H13: =الافتراضات!$C$13 -> 273.64 | I13: =الافتراضات!$C$8 -> 1150000 | J13: =IFERROR(I13/H13,0) -> 4202.602 | K13: عرض حالي | L13: بروشور المشروع + الافتراضات
D14: مشروعنا – محسوباً على المساحة فوق الأرض فقط (بدون القبو) | H14: =الافتراضات!$C$14 -> 202.24 | I14: =الافتراضات!$C$8 -> 1150000 | J14: =IFERROR(I14/H14,0) -> 5686.3133
D15: الخلايا البرتقالية في عمود السعر = وحدات أغلى من سعرنا
B28: ملخص تاون هاوس القادسية مقارنة بسعرنا
C29: الحي | D29: عدد العروض | E29: متوسط سعر الوحدة | F29: أعلى سعر وحدة | G29: متوسط المساحة م² | H29: متوسط سعر المتر
C30: القادسية | D30: =COUNTIF($C$6:$C$12,C30) -> 7 | E30: =IFERROR(AVERAGEIF($C$6:$C$12,C30,$I$6:$I$12),0) -> 1300000 | F30: =_xlfn.MAXIFS($I$6:$I$12,$C$6:$C$12,C30) -> 1500000 | G30: =IFERROR(AVERAGEIF($C$6:$C$12,C30,$H$6:$H$12),0) -> 235.14286 | H30: =IFERROR(AVERAGEIF($C$6:$C$12,C30,$J$6:$J$12),0) -> 5575.4799
C31: مشروعنا | D31: =الافتراضات!$C$7 -> 12 | E31: =I13 -> 1150000 | F31: =I13 -> 1150000 | G31: =H13 -> 273.64 | H31: =J13 -> 4202.602
B33: أين يقف سعرنا في القادسية؟
C34: عدد وحدات القادسية المرصودة الأغلى من سعرنا | I34: =COUNTIFS($C$6:$C$12,"القادسية",$I$6:$I$12,">"&I13) -> 7
C35: سعر وحدتنا أقل من متوسط سعر الوحدة في القادسية بـ (ريال) | I35: =E30-E31 -> 150000
C36: نسبة الخصم عن متوسط سعر الوحدة في القادسية | I36: =IFERROR(1-E31/E30,0) -> 0.11538462
C37: نسبة الخصم عن أغلى تاون هاوس في القادسية | I37: =IFERROR(1-E31/F30,0) -> 0.23333333
C38: مساحتنا أكبر من متوسط مساحة القادسية بـ (م²) | I38: =G31-G30 -> 38.497143
C39: خصم سعر المتر عن متوسط القادسية (على إجمالي المساحة) | I39: =IFERROR(1-H31/H30,0) -> 0.24623494
C40: خصم سعر المتر عن متوسط القادسية (على المساحة فوق الأرض فقط) | I40: =IFERROR(1-J14/H30,0) -> -0.019878715
C42: ملاحظات: (1) بعض الإعلانات تذكر مساحة الأرض وبعضها مسطح البناء. (2) "غير مذكور" = الميزة لم تُذكر في نص الإعلان. (3) مشاريع مطورين أخرى في القادسية بدون أسعار معلنة: "نجد الأول" من ريبورتاج (24 تاون هاوس) و"أملا" (14 فيلا متصلة). (4) يُنصح بالتحقق الميداني قبل العرض النهائي.

Sheet العائد على المستثمر
B2: العائد على المستثمر – إعادة البيع بعد التسليم + التأجير
B4: أ) تكلفة الصفقة والمكسب الفوري
B5: قيمة الشراء (12 وحدة) | C5: =الافتراضات!$C$7*الافتراضات!$C$8 -> 13800000
B6: ضريبة التصرفات + السعي عند الشراء | C6: =C5*(الافتراضات!$C$16+الافتراضات!$C$17) -> 690000
B7: إجمالي تكلفة الاستثمار | C7: =C5+C6 -> 14490000
B8: قيمة الوحدات بسعر البيع للأفراد | C8: =الافتراضات!$C$7*الافتراضات!$C$25 -> 16200000
B9: قيمة الوحدات بمتوسط سعر وحدة القادسية | C9: =الافتراضات!$C$7*'المقارنات السعرية'!E30 -> 15600000
B10: مكسب فوري مقابل سعر البيع للأفراد | C10: =C8-C5 -> 2400000
B12: ب) التدفقات النقدية – البيع عند التسليم (فترات نصف سنوية)
B13: البند | C13: شهر 0 | D13: شهر 6 | E13: شهر 12 | F13: شهر 18 | G13: شهر 24 | H13: الإجمالي
B14: دفعات الشراء | C14: =-الافتراضات!$C$19*$C$5 -> -13800000 | D14: =-الافتراضات!$C$20*$C$5 -> 0 | E14: =-الافتراضات!$C$21*$C$5 -> 0 | F14: =-الافتراضات!$C$22*$C$5 -> 0 | G14: =-الافتراضات!$C$23*$C$5 -> 0 | H14: =SUM(C14:G14) -> -13800000
B15: ضريبة التصرفات والسعي (عند التوقيع) | C15: =IF(0=0,-$C$6,0) -> -690000 | D15: =IF(1=0,-$C$6,0) -> 0 | E15: =IF(2=0,-$C$6,0) -> 0 | F15: =IF(3=0,-$C$6,0) -> 0 | G15: =IF(4=0,-$C$6,0) -> 0 | H15: =SUM(C15:G15) -> -690000
B16: متحصلات بيع الوحدات | C16: =IF(0*0.5=ROUND(الافتراضات!$C$28,1),الافتراضات!$C$7*الافتراضات!$C$29,0) -> 0 | D16: =IF(1*0.5=ROUND(الافتراضات!$C$28,1),الافتراضات!$C$7*الافتراضات!$C$29,0) -> 0 | E16: =IF(2*0.5=ROUND(الافتراضات!$C$28,1),الافتراضات!$C$7*الافتراضات!$C$29,0) -> 0 | F16: =IF(3*0.5=ROUND(الافتراضات!$C$28,1),الافتراضات!$C$7*الافتراضات!$C$29,0) -> 0 | G16: =IF(4*0.5=ROUND(الافتراضات!$C$28,1),الافتراضات!$C$7*الافتراضات!$C$29,0) -> 16200000 | H16: =SUM(C16:G16) -> 16200000
B17: عمولة البيع وضريبة التصرفات | C17: =-C16*(الافتراضات!$C$30+الافتراضات!$C$31) -> 0 | D17: =-D16*(الافتراضات!$C$30+الافتراضات!$C$31) -> 0 | E17: =-E16*(الافتراضات!$C$30+الافتراضات!$C$31) -> 0 | F17: =-F16*(الافتراضات!$C$30+الافتراضات!$C$31) -> 0 | G17: =-G16*(الافتراضات!$C$30+الافتراضات!$C$31) -> -1215000 | H17: =SUM(C17:G17) -> -1215000
B18: صافي التدفق النقدي | C18: =SUM(C14:C17) -> -14490000 | D18: =SUM(D14:D17) -> 0 | E18: =SUM(E14:E17) -> 0 | F18: =SUM(F14:F17) -> 0 | G18: =SUM(G14:G17) -> 14985000 | H18: =SUM(C18:G18) -> 495000
B19: التدفق التراكمي | C19: =SUM($C$18:C18) -> -14490000 | D19: =SUM($C$18:D18) -> -14490000 | E19: =SUM($C$18:E18) -> -14490000 | F19: =SUM($C$18:F18) -> -14490000 | G19: =SUM($C$18:G18) -> 495000 | H19: =G19 -> 495000
B21: ج) مؤشرات الربحية – سيناريو البيع
B22: صافي الربح (ريال) | C22: =H18 -> 495000
B23: العائد الكلي على رأس المال (ROI) | C23: =IFERROR(H18/-SUMIF(C18:G18,"<0"),0) -> 0.034161491
B24: العائد السنوي البسيط | C24: =IFERROR(C23/الافتراضات!$C$28,0) -> 0.017080745
B25: معدل العائد الداخلي السنوي (IRR) | C25: =IFERROR((1+IRR(C18:G18))^2-1,0) -> 0.016937309
B26: سعر بيع الوحدة للتعادل (ريال) | C26: =IFERROR(C7/(1-الافتراضات!$C$30-الافتراضات!$C$31)/الافتراضات!$C$7,0) -> 1305405.4
B27: هامش الأمان: انخفاض سعر البيع المسموح قبل الخسارة | C27: =IFERROR(1-C26/الافتراضات!$C$29,0) -> 0.033033033
B29: د) الحساسية – صافي الربح حسب سعر إعادة البيع ومن يتحمل ضريبة الشراء
B30: سعر بيع الوحدة (ريال) | C30: صافي الربح – المستثمر يدفع ضريبة الشراء | D30: ROI | E30: صافي الربح – المطور يتحمل ضريبة الشراء | F30: ROI | G30: IRR سنوي (المطور يتحمل)
B31: 1200000 | C31: =الافتراضات!$C$7*B31*(1-الافتراضات!$C$30-الافتراضات!$C$31)-الافتراضات!$C$7*الافتراضات!$C$8*(1+الافتراضات!$C$16+الافتراضات!$C$17) -> -1170000 | D31: =IFERROR(C31/(الافتراضات!$C$7*الافتراضات!$C$8*(1+الافتراضات!$C$16+الافتراضات!$C$17)),0) -> -0.080745342 | E31: =الافتراضات!$C$7*B31*(1-الافتراضات!$C$30-الافتراضات!$C$31)-الافتراضات!$C$7*الافتراضات!$C$8*(1+الافتراضات!$C$17) -> -480000 | F31: =IFERROR(E31/(الافتراضات!$C$7*الافتراضات!$C$8*(1+الافتراضات!$C$17)),0) -> -0.034782609 | G31: =IFERROR((الافتراضات!$C$7*B31*(1-الافتراضات!$C$30-الافتراضات!$C$31)/(الافتراضات!$C$7*الافتراضات!$C$8*(1+الافتراضات!$C$17)))^(1/الافتراضات!$C$28)-1,0) -> -0.017545222
B32: 1250000 | C32: =الافتراضات!$C$7*B32*(1-الافتراضات!$C$30-الافتراضات!$C$31)-الافتراضات!$C$7*الافتراضات!$C$8*(1+الافتراضات!$C$16+الافتراضات!$C$17) -> -615000 | D32: =IFERROR(C32/(الافتراضات!$C$7*الافتراضات!$C$8*(1+الافتراضات!$C$16+الافتراضات!$C$17)),0) -> -0.042443064 | E32: =الافتراضات!$C$7*B32*(1-الافتراضات!$C$30-الافتراضات!$C$31)-الافتراضات!$C$7*الافتراضات!$C$8*(1+الافتراضات!$C$17) -> 75000 | F32: =IFERROR(E32/(الافتراضات!$C$7*الافتراضات!$C$8*(1+الافتراضات!$C$17)),0) -> 0.0054347826 | G32: =IFERROR((الافتراضات!$C$7*B32*(1-الافتراضات!$C$30-الافتراضات!$C$31)/(الافتراضات!$C$7*الافتراضات!$C$8*(1+الافتراضات!$C$17)))^(1/الافتراضات!$C$28)-1,0) -> 0.0027137092
B33: 1300000 | C33: =الافتراضات!$C$7*B33*(1-الافتراضات!$C$30-الافتراضات!$C$31)-الافتراضات!$C$7*الافتراضات!$C$8*(1+الافتراضات!$C$16+الافتراضات!$C$17) -> -60000 | D33: =IFERROR(C33/(الافتراضات!$C$7*الافتراضات!$C$8*(1+الافتراضات!$C$16+الافتراضات!$C$17)),0) -> -0.0041407867 | E33: =الافتراضات!$C$7*B33*(1-الافتراضات!$C$30-الافتراضات!$C$31)-الافتراضات!$C$7*الافتراضات!$C$8*(1+الافتراضات!$C$17) -> 630000 | F33: =IFERROR(E33/(الافتراضات!$C$7*الافتراضات!$C$8*(1+الافتراضات!$C$17)),0) -> 0.045652174 | G33: =IFERROR((الافتراضات!$C$7*B33*(1-الافتراضات!$C$30-الافتراضات!$C$31)/(الافتراضات!$C$7*الافتراضات!$C$8*(1+الافتراضات!$C$17)))^(1/الافتراضات!$C$28)-1,0) -> 0.022571354
B34: 1350000 | C34: =الافتراضات!$C$7*B34*(1-الافتراضات!$C$30-الافتراضات!$C$31)-الافتراضات!$C$7*الافتراضات!$C$8*(1+الافتراضات!$C$16+الافتراضات!$C$17) -> 495000 | D34: =IFERROR(C34/(الافتراضات!$C$7*الافتراضات!$C$8*(1+الافتراضات!$C$16+الافتراضات!$C$17)),0) -> 0.034161491 | E34: =الافتراضات!$C$7*B34*(1-الافتراضات!$C$30-الافتراضات!$C$31)-الافتراضات!$C$7*الافتراضات!$C$8*(1+الافتراضات!$C$17) -> 1185000 | F34: =IFERROR(E34/(الافتراضات!$C$7*الافتراضات!$C$8*(1+الافتراضات!$C$17)),0) -> 0.085869565 | G34: =IFERROR((الافتراضات!$C$7*B34*(1-الافتراضات!$C$30-الافتراضات!$C$31)/(الافتراضات!$C$7*الافتراضات!$C$8*(1+الافتراضات!$C$17)))^(1/الافتراضات!$C$28)-1,0) -> 0.042050654
B35: 1400000 | C35: =الافتراضات!$C$7*B35*(1-الافتراضات!$C$30-الافتراضات!$C$31)-الافتراضات!$C$7*الافتراضات!$C$8*(1+الافتراضات!$C$16+الافتراضات!$C$17) -> 1050000 | D35: =IFERROR(C35/(الافتراضات!$C$7*الافتراضات!$C$8*(1+الافتراضات!$C$16+الافتراضات!$C$17)),0) -> 0.072463768 | E35: =الافتراضات!$C$7*B35*(1-الافتراضات!$C$30-الافتراضات!$C$31)-الافتراضات!$C$7*الافتراضات!$C$8*(1+الافتراضات!$C$17) -> 1740000 | F35: =IFERROR(E35/(الافتراضات!$C$7*الافتراضات!$C$8*(1+الافتراضات!$C$17)),0) -> 0.12608696 | G35: =IFERROR((الافتراضات!$C$7*B35*(1-الافتراضات!$C$30-الافتراضات!$C$31)/(الافتراضات!$C$7*الافتراضات!$C$8*(1+الافتراضات!$C$17)))^(1/الافتراضات!$C$28)-1,0) -> 0.061172444
B36: 1450000 | C36: =الافتراضات!$C$7*B36*(1-الافتراضات!$C$30-الافتراضات!$C$31)-الافتراضات!$C$7*الافتراضات!$C$8*(1+الافتراضات!$C$16+الافتراضات!$C$17) -> 1605000 | D36: =IFERROR(C36/(الافتراضات!$C$7*الافتراضات!$C$8*(1+الافتراضات!$C$16+الافتراضات!$C$17)),0) -> 0.11076605 | E36: =الافتراضات!$C$7*B36*(1-الافتراضات!$C$30-الافتراضات!$C$31)-الافتراضات!$C$7*الافتراضات!$C$8*(1+الافتراضات!$C$17) -> 2295000 | F36: =IFERROR(E36/(الافتراضات!$C$7*الافتراضات!$C$8*(1+الافتراضات!$C$17)),0) -> 0.16630435 | G36: =IFERROR((الافتراضات!$C$7*B36*(1-الافتراضات!$C$30-الافتراضات!$C$31)/(الافتراضات!$C$7*الافتراضات!$C$8*(1+الافتراضات!$C$17)))^(1/الافتراضات!$C$28)-1,0) -> 0.079955716
B37: 1500000 | C37: =الافتراضات!$C$7*B37*(1-الافتراضات!$C$30-الافتراضات!$C$31)-الافتراضات!$C$7*الافتراضات!$C$8*(1+الافتراضات!$C$16+الافتراضات!$C$17) -> 2160000 | D37: =IFERROR(C37/(الافتراضات!$C$7*الافتراضات!$C$8*(1+الافتراضات!$C$16+الافتراضات!$C$17)),0) -> 0.14906832 | E37: =الافتراضات!$C$7*B37*(1-الافتراضات!$C$30-الافتراضات!$C$31)-الافتراضات!$C$7*الافتراضات!$C$8*(1+الافتراضات!$C$17) -> 2850000 | F37: =IFERROR(E37/(الافتراضات!$C$7*الافتراضات!$C$8*(1+الافتراضات!$C$17)),0) -> 0.20652174 | G37: =IFERROR((الافتراضات!$C$7*B37*(1-الافتراضات!$C$30-الافتراضات!$C$31)/(الافتراضات!$C$7*الافتراضات!$C$8*(1+الافتراضات!$C$17)))^(1/الافتراضات!$C$28)-1,0) -> 0.098417834
B38: 1550000 | C38: =الافتراضات!$C$7*B38*(1-الافتراضات!$C$30-الافتراضات!$C$31)-الافتراضات!$C$7*الافتراضات!$C$8*(1+الافتراضات!$C$16+الافتراضات!$C$17) -> 2715000 | D38: =IFERROR(C38/(الافتراضات!$C$7*الافتراضات!$C$8*(1+الافتراضات!$C$16+الافتراضات!$C$17)),0) -> 0.1873706 | E38: =الافتراضات!$C$7*B38*(1-الافتراضات!$C$30-الافتراضات!$C$31)-الافتراضات!$C$7*الافتراضات!$C$8*(1+الافتراضات!$C$17) -> 3405000 | F38: =IFERROR(E38/(الافتراضات!$C$7*الافتراضات!$C$8*(1+الافتراضات!$C$17)),0) -> 0.24673913 | G38: =IFERROR((الافتراضات!$C$7*B38*(1-الافتراضات!$C$30-الافتراضات!$C$31)/(الافتراضات!$C$7*الافتراضات!$C$8*(1+الافتراضات!$C$17)))^(1/الافتراضات!$C$28)-1,0) -> 0.11657473
B39: الحساسية تفترض سداد كامل المبلغ مقدماً والبيع بعد المدة المحددة. عروض القادسية المرصودة بين 1.2 و1.5 مليون.
B41: هـ) سيناريو بديل – الاحتفاظ بالوحدات وتأجيرها
B42: إجمالي الإيجار السنوي (12 وحدة) | C42: =الافتراضات!$C$7*الافتراضات!$C$33 -> 900000
B43: بعد نسبة الإشغال | C43: =C42*الافتراضات!$C$34 -> 855000
B44: صافي الدخل التشغيلي بعد المصاريف | C44: =C43*(1-الافتراضات!$C$35) -> 795150
B45: العائد الإيجاري الإجمالي على سعر الشراء | C45: =IFERROR(C42/C5,0) -> 0.065217391
B46: صافي العائد الإيجاري على إجمالي التكلفة | C46: =IFERROR(C44/C7,0) -> 0.054875776
...
